Workbook

Sheet Dashboard
A6: Production Trend
A20: Inventory Overview
A35: Maintenance & Manpower

Sheet FG Store
A1: =TODAY()-1 -> 46169 | F1: =SUMIF(A3:A128,A1,F3:F128) -> 389028.68
A2: S/N | B2: Product Name | C2: Category | D2: Prod WT. | E2: Stock | F2: In Kgs
A3: 46169 | B3: Powercool - 2 Ltr | C3: Virgin | D3: 0.3905 | E3: 2183.96 | F3: 852.83638
A4: 46169 | B4: Powercool - 3Ltr | C4: Virgin | D4: 0.4788 | E4: 8153 | F4: 3903.6564 | J4: Recycled | K4: =SUMIF(C2:C127,J4,F2:F127) -> 250085.88
A5: 46169 | B5: Powercool - 5Ltr | C5: Virgin | D5: 0.6475 | E5: 9750 | F5: 6313.125 | J5: Virgin | K5: =SUMIF(C4:C129,J5,F4:F129) -> 87973.632
A6: 46169 | B6: ZAFI CASSEROLE SET (2Ltr) | C6: Recycled | D6: 0.3685 | E6: - | F6: - | J6: Corporate | K6: =SUMIF(C3:C128,J6,F3:F128) -> 50116.332
A7: 46169 | B7: ZAFI CASSEROLE SET (1.5 Ltr) | C7: Recycled | D7: 0.232 | E7: - | F7: -
A8: 46169 | B8: POWERCOOL 25 | C8: Virgin | D8: 2.155 | E8: 6 | F8: 12.93
A9: 46169 | B9: POWERCOOL 35 | C9: Virgin | D9: 3.05 | E9: 45 | F9: 137.25
A10: 46169 | B10: STAR FLOWER POT (LARGE) | C10: Recycled | D10: 1.35 | E10: 157 | F10: 211.95
A11: 46169 | B11: STAR FLOWER POT (Medium) | C11: Recycled | D11: 0.88 | E11: 4609 | F11: 4055.92
A12: 46169 | B12: STAR FLOWER POT (S) - 12 Pcs/Bag | C12: Recycled | D12: 0.58 | E12: 11085.48 | F12: 6429.5784
A13: 46169 | B13: DELUXE FLOWER POT | C13: Recycled | D13: 0.27 | E13: 3520 | F13: 950.4
A14: 46169 | B14: SUPER FLOWER POT | C14: Recycled | D14: 0.385 | E14: 1418 | F14: 545.93
A15: 46169 | B15: Storage Box Large (6 Pcs/Bag) | C15: Virgin | D15: 1.5 | E15: 5435 | F15: 8152.5
A16: 46169 | B16: Storage Box Medium - (6pcs/Bag) | C16: Virgin | D16: 0.904 | E16: 2696 | F16: 2437.184
A17: 46169 | B17: Storage Box Small - (12pcs/Bag) | C17: Virgin | D17: 0.409 | E17: 7656 | F17: 3131.304
A18: 46169 | B18: Papilon Keep Afresh Cont - Large - (12Pcs/Bag) | C18: Virgin | D18: 0.806 | E18: 4781.16 | F18: 3853.615
A19: 46169 | B19: Papilon Keep Afresh Cont - Medium -(12Pcs/Bag) | C19: Virgin | D19: 0.424 | E19: 261 | F19: 110.664
... A128: 46169 | B128: Papilon 100gm Container (500 Pcs/Bag) | C128: Corporate | D128: 0.0095 | E128: 664500 | F128: 6312.75

Sheet Sheet4
A3: Row Labels | B3: Sum of Target In Kgs | C3: Sum of Achieved in Kgs
A4: TFM | B4: 2313 | C4: 2239.32
A5: MI | B5: 12897 | C5: 6448.1634
A6: LI | B6: 21046 | C6: 16655.055
A7: IBM | B7: 1257 | C7: 1135.236
A8: HT | B8: 5805 | C8: 3787.0657
A9: Blow | B9: 1288 | C9: 275.556
A10: Grand Total | B10: 44606 | C10: 30540.396

Sheet Production
A1: =TODAY()-1 -> 46169 | D1: =SUMIF(A3:A60,A1,D3:D60) -> 44606 | E1: =SUMIF(A3:A60,A1,E3:E60) -> 30540.396 | F1: =E1/D1 -> 0.68467014
A2: Date | B2: Department | C2: Machine | D2: Target In Kgs | E2: Achieved in Kgs | F2: Var %
A3: 46169 | B3: LI | C3: LI-40-HT-600 | D3: 1140 | E3: 856.68 | F3: =IFERROR(E3/D3,"-") -> 0.75147368
A4: 46169 | B4: LI | C4: LI-41-HXM-630 | D4: 1659 | E4: 1024.32 | F4: =IFERROR(E4/D4,"-") -> 0.61743219
A5: 46169 | B5: LI | C5: LI-42-HT-700 | D5: 3486 | E5: 2884.2 | F5: =IFERROR(E5/D5,"-") -> 0.82736661
A6: 46169 | B6: LI | C6: LI-43-OM-910 | D6: 3388 | E6: 1933.755 | F6: =IFERROR(E6/D6,"-") -> 0.57076594
A7: 46169 | B7: LI | C7: LI-44-HXM-830 | D7: 2222 | E7: 1109.7 | F7: =IFERROR(E7/D7,"-") -> 0.49941494
A8: 46169 | B8: LI | C8: LI-45-HT-1000 | D8: 3613 | E8: 3629.4 | F8: =IFERROR(E8/D8,"-") -> 1.0045392
A9: 46169 | B9: LI | C9: LI-46-HT-1000 | D9: 3486 | E9: 3362.6 | F9: =IFERROR(E9/D9,"-") -> 0.96460126
A10: 46169 | B10: LI | C10: LI-47-HXM-1100 | D10: 2052 | E10: 1854.4 | F10: =IFERROR(E10/D10,"-") -> 0.9037037
A11: 46169 | B11: MI | C11: MI-01-HT-86 | D11: 103 | E11: 130.758 | F11: =IFERROR(E11/D11,"-") -> 1.2694951
A12: 46169 | B12: MI | C12: MI-02-HT-86 | D12: 92 | E12: 3.7758 | F12: =IFERROR(E12/D12,"-") -> 0.041041304
A13: 46169 | B13: MI | C13: MI-02-HT-86 | D13: 55 | E13: 54.264 | F13: =IFERROR(E13/D13,"-") -> 0.98661818
A14: 46169 | B14: MI | C14: MI-03-FU-110 | D14: 221 | E14: 174.8 | F14: =IFERROR(E14/D14,"-") -> 0.79095023
... A54: 46169 | B54: IBM | C54: HT-49-IBM-50B | D54: 436 | E54: 343.75 | F54: =IFERROR(E54/D54,"-") -> 0.78841743
A55: 46169 | B55: IBM | C55: HT-50-IBM-50C | D55: - | E55: - | F55: =IFERROR(E55/D55,"-") -> -
A56: 46169 | B56: IBM | C56: HT-51-IBM-50D | D56: 448 | E56: 448.286 | F56: =IFERROR(E56/D56,"-") -> 1.0006384
A57: 46169 | B57: TFM | C57: TFM-1 | D57: 507 | E57: 654.72 | F57: =IFERROR(E57/D57,"-") -> 1.2913609
A58: 46169 | B58: TFM | C58: TFM-2 | D58: 1806 | E58: 1584.6 | F58: =IFERROR(E58/D58,"-") -> 0.87740864
A59: 46169 | B59: Blow | C59: BL-JM-5ltr | D59: 819 | E59: 63.656 | F59: =IFERROR(E59/D59,"-") -> 0.077724054
A60: 46169 | B60: Blow | C60: BL-JM-15ltr | D60: 469 | E60: 211.9 | F60: =IFERROR(E60/D60,"-") -> 0.45181237

Sheet Machines
A1: S/N | B1: Machines | C1: Status | E1: Running | F1: =COUNTIF(C2:C54,E1) -> 42 | I1: Production Support
A2: 1 | B2: LI-40-HT-600 | C2: Running | E2: Idle | F2: =COUNTIF(C2:C55,E2) -> 3 | I2: S/N | J2: Support Department | K2: Running Status
A3: 2 | B3: LI-41-HXM-630 | C3: Running | E3: Breakdown | F3: =COUNTIF(C2:C56,E3) -> 8 | I3: 1 | J3: Pet Blow | K3: Running
A4: 3 | B4: LI-42-HT-700 | C4: Running | E4: Total Machines | F4: =SUM(F1:F3) -> 53 | I4: 2 | J4: Foiling | K4: Running
A5: 4 | B5: LI-43-OM-910 | C5: Running | I5: 3 | J5: Grinding | K5: Running
A6: 5 | B6: LI-44-HXM-830 | C6: Running | I6: 4 | J6: Ultrasonic Welding | K6: Idle
A7: 6 | B7: LI-45-HT-1000 | C7: Running | I7: 5 | J7: Mixing Section | K7: Running
A8: 7 | B8: LI-46-HT-1000 | C8: Running | I8: 6 | J8: Assembly | K8: Active
A9: 8 | B9: LI-47-HXM-1100 | C9: Running | F9: Mold / Machines | G9: Durations
A10: 9 | B10: MI-01-HT-86 | C10: Running | F10: MI-01-HT-86 | G10: 0.10416667
A11: 10 | B11: MI-02-HT-86 | C11: Running | F11: MI-02-HT-86 | G11: 0.10625
A12: 11 | B12: MI-03-FU-110 | C12: Running | F12: MI-03-FU-110 | G12: 0.072916667
A13: 12 | B13: MI-04-FU-110 | C13: Running | F13: MI-04-FU-110 | G13: 0.15625
A14: 13 | B14: MI-05-HT-120 | C14: Running | F14: MI-05-HT-120 | G14: 0.034722222
A15: 14 | B15: MI-06-HT-120 | C15: Running | F15: Papilon Chair | G15: 0.13472222
A16: 15 | B16: MI-07-HT-120 | C16: Running | F16: Papilon Lion Chair | G16: 0.095833333
A17: 16 | B17: MI-08-FU-150 | C17: Running | F17: 160ltr Drum Body | G17: 0.13680556
A18: 17 | B18: MI-09-FU-150 | C18: Running | F18: The Place Container | G18: 0.041666667
A19: 18 | B19: MI-10-HT-160 | C19: Running | F19: Pet Blow Compressor | G19: 0.083333333
A20: 19 | B20: MI-11-HT-160 | C20: Running | F20: Chiller Compressor | G20: 0.5
A21: 20 | B21: MI-12-HT-160 | C21: Running | F21: Average | G21: =IFERROR(AVERAGE(G10:G20),"-") -> 0.13333333
A22: 21 | B22: MI-13-FU-180 | C22: Running
A23: 22 | B23: MI-15-HT-200 | C23: Running
A24: 23 | B24: MI-16-HT-200 | C24: Running
A25: 24 | B25: MI-17-HT-200 | C25: Running
A26: 25 | B26: MI-18-HT-250 | C26: Running
A27: 26 | B27: MI-19-HT-250 | C27: Running
A28: 27 | B28: MI-20-FU-280 | C28: Running
A29: 28 | B29: MI-21-HT-300 | C29: Running
A30: 29 | B30: MI-22-HT-300 | C30: Running
A31: 30 | B31: MI-23-HT-300 | C31: Running
A32: 31 | B32: MI-24-OM-350 | C32: Breakdown
A33: 32 | B33: MI-25-OM-350 | C33: Breakdown
... A54: 53 | B54: TFM-2 | C54: Running

Sheet Production vs Sales
A1: =TODAY()-1 -> 46169 | E1: =SUMIF(A3:A300,A1,E3:E300) -> 23793.386 | G1: =SUMIF(A3:A300,A1,G3:G300) -> 16388.37 | L1: Sales Target: | M1: 30000
A2: Date | B2: Product Name | C2: Prod WT. | D2: Produced Qty | E2: Produced Kgs | F2: Sales Qty | G2: Sales Kgs
A3: 46169 | B3: Powercool - 2 Ltr | C3: =_xlfn.XLOOKUP(B3,'Prod FG'!B:B,'Prod FG'!C:C,"-") -> 0.3905 | D3: 0 | E3: =IFERROR(D3*C3,"-") -> 0 | F3: 312 | G3: =IFERROR(F3*C3,"-") -> 121.836
A4: 46169 | B4: Powercool - 3Ltr | C4: =_xlfn.XLOOKUP(B4,'Prod FG'!B:B,'Prod FG'!C:C,"-") -> 0.4788 | D4: 0 | E4: =IFERROR(D4*C4,"-") -> 0 | F4: 36 | G4: =IFERROR(F4*C4,"-") -> 17.2368 | L4: Production | M4: =E1 -> 23793.386
A5: 46169 | B5: Powercool - 5Ltr | C5: =_xlfn.XLOOKUP(B5,'Prod FG'!B:B,'Prod FG'!C:C,"-") -> 0.6475 | D5: 0 | E5: =IFERROR(D5*C5,"-") -> 0 | F5: 48 | G5: =IFERROR(F5*C5,"-") -> 31.08 | L5: Sales | M5: =G1 -> 16388.37
A6: 46169 | B6: ZAFI CASSEROLE SET (2Ltr) | C6: =_xlfn.XLOOKUP(B6,'Prod FG'!B:B,'Prod FG'!C:C,"-") -> 0.3685 | D6: 0 | E6: =IFERROR(D6*C6,"-") -> 0 | F6: 0 | G6: =IFERROR(F6*C6,"-") -> 0
A7: 46169 | B7: ZAFI CASSEROLE SET (1.5 Ltr) | C7: =_xlfn.XLOOKUP(B7,'Prod FG'!B:B,'Prod FG'!C:C,"-") -> 0.232 | D7: 0 | E7: =IFERROR(D7*C7,"-") -> 0 | F7: 0 | G7: =IFERROR(F7*C7,"-") -> 0
A8: 46169 | B8: POWERCOOL 25 | C8: =_xlfn.XLOOKUP(B8,'Prod FG'!B:B,'Prod FG'!C:C,"-") -> 2.155 | D8: 0 | E8: =IFERROR(D8*C8,"-") -> 0 | F8: 0 | G8: =IFERROR(F8*C8,"-") -> 0
A9: 46169 | B9: POWERCOOL 35 | C9: =_xlfn.XLOOKUP(B9,'Prod FG'!B:B,'Prod FG'!C:C,"-") -> 3.05 | D9: 0 | E9: =IFERROR(D9*C9,"-") -> 0 | F9: 0 | G9: =IFERROR(F9*C9,"-") -> 0
A10: 46169 | B10: STAR FLOWER POT (LARGE) | C10: =_xlfn.XLOOKUP(B10,'Prod FG'!B:B,'Prod FG'!C:C,"-") -> 1.35 | D10: 0 | E10: =IFERROR(D10*C10,"-") -> 0 | F10: 0 | G10: =IFERROR(F10*C10,"-") -> 0
A11: 46169 | B11: STAR FLOWER POT (Medium) | C11: =_xlfn.XLOOKUP(B11,'Prod FG'!B:B,'Prod FG'!C:C,"-") -> 0.88 | D11: 0 | E11: =IFERROR(D11*C11,"-") -> 0 | F11: 0 | G11: =IFERROR(F11*C11,"-") -> 0
A12: 46169 | B12: STAR FLOWER POT (S) - 12 Pcs/Bag | C12: =_xlfn.XLOOKUP(B12,'Prod FG'!B:B,'Prod FG'!C:C,"-") -> 0.58 | D12: 0 | E12: =IFERROR(D12*C12,"-") -> 0 | F12: 0 | G12: =IFERROR(F12*C12,"-") -> 0
A13: 46169 | B13: DELUXE FLOWER POT | C13: =_xlfn.XLOOKUP(B13,'Prod FG'!B:B,'Prod FG'!C:C,"-") -> 0.27 | D13: 0 | E13: =IFERROR(D13*C13,"-") -> 0 | F13: 0 | G13: =IFERROR(F13*C13,"-") -> 0
A14: 46169 | B14: SUPER FLOWER POT | C14: =_xlfn.XLOOKUP(B14,'Prod FG'!B:B,'Prod FG'!C:C,"-") -> 0.385 | D14: 360 | E14: =IFERROR(D14*C14,"-") -> 138.6 | F14: 0 | G14: =IFERROR(F14*C14,"-") -> 0
A15: 46169 | B15: Storage Box Large (6 Pcs/Bag) | C15: =_xlfn.XLOOKUP(B15,'Prod FG'!B:B,'Prod FG'!C:C,"-") -> 1.5 | D15: 0 | E15: =IFERROR(D15*C15,"-") -> 0 | F15: 30 | G15: =IFERROR(F15*C15,"-") -> 45
A16: 46169 | B16: Storage Box Medium - (6pcs/Bag) | C16: =_xlfn.XLOOKUP(B16,'Prod FG'!B:B,'Prod FG'!C:C,"-") -> 0.904 | D16: 0 | E16: =IFERROR(D16*C16,"-") -> 0 | F16: 30 | G16: =IFERROR(F16*C16,"-") -> 27.12
A17: 46169 | B17: Storage Box Small - (12pcs/Bag) | C17: =_xlfn.XLOOKUP(B17,'Prod FG'!B:B,'Prod FG'!C:C,"-") -> 0.409 | D17: 0 | E17: =IFERROR(D17*C17,"-") -> 0 | F17: 120 | G17: =IFERROR(F17*C17,"-") -> 49.08
... A128: 46169 | B128: Papilon 100gm Container (500 Pcs/Bag) | C128: =_xlfn.XLOOKUP(B128,'Prod FG'!B:B,'Prod FG'!C:C,"-") -> 0.0095 | D128: 0 | E128: =IFERROR(D128*C128,"-") -> 0 | F128: 0 | G128: =IFERROR(F128*C128,"-") -> 0
C129: =_xlfn.XLOOKUP(B129,'Prod FG'!B:B,'Prod FG'!C:C,"-") -> 0 | E129: =IFERROR(D129*C129,"-") -> 0 | G129: =IFERROR(F129*C129,"-") -> 0
C130: =_xlfn.XLOOKUP(B130,'Prod FG'!B:B,'Prod FG'!C:C,"-") -> 0 | E130: =IFERROR(D130*C130,"-") -> 0 | G130: =IFERROR(F130*C130,"-") -> 0
C131: =_xlfn.XLOOKUP(B131,'Prod FG'!B:B,'Prod FG'!C:C,"-") -> 0 | E131: =IFERROR(D131*C131,"-") -> 0 | G131: =IFERROR(F131*C131,"-") -> 0
C132: =_xlfn.XLOOKUP(B132,'Prod FG'!B:B,'Prod FG'!C:C,"-") -> 0 | E132: =IFERROR(D132*C132,"-") -> 0 | G132: =IFERROR(F132*C132,"-") -> 0
C133: =_xlfn.XLOOKUP(B133,'Prod FG'!B:B,'Prod FG'!C:C,"-") -> 0 | E133: =IFERROR(D133*C133,"-") -> 0 | G133: =IFERROR(F133*C133,"-") -> 0
C134: =_xlfn.XLOOKUP(B134,'Prod FG'!B:B,'Prod FG'!C:C,"-") -> 0 | E134: =IFERROR(D134*C134,"-") -> 0 | G134: =IFERROR(F134*C134,"-") -> 0
C135: =_xlfn.XLOOKUP(B135,'Prod FG'!B:B,'Prod FG'!C:C,"-") -> 0 | E135: =IFERROR(D135*C135,"-") -> 0 | G135: =IFERROR(F135*C135,"-") -> 0
C136: =_xlfn.XLOOKUP(B136,'Prod FG'!B:B,'Prod FG'!C:C,"-") -> 0 | E136: =IFERROR(D136*C136,"-") -> 0 | G136: =IFERROR(F136*C136,"-") -> 0
C137: =_xlfn.XLOOKUP(B137,'Prod FG'!B:B,'Prod FG'!C:C,"-") -> 0 | E137: =IFERROR(D137*C137,"-") -> 0 | G137: =IFERROR(F137*C137,"-") -> 0
C138: =_xlfn.XLOOKUP(B138,'Prod FG'!B:B,'Prod FG'!C:C,"-") -> 0 | E138: =IFERROR(D138*C138,"-") -> 0 | G138: =IFERROR(F138*C138,"-") -> 0
C139: =_xlfn.XLOOKUP(B139,'Prod FG'!B:B,'Prod FG'!C:C,"-") -> 0 | E139: =IFERROR(D139*C139,"-") -> 0 | G139: =IFERROR(F139*C139,"-") -> 0
C140: =_xlfn.XLOOKUP(B140,'Prod FG'!B:B,'Prod FG'!C:C,"-") -> 0 | E140: =IFERROR(D140*C140,"-") -> 0 | G140: =IFERROR(F140*C140,"-") -> 0
... C300: =_xlfn.XLOOKUP(B300,'Prod FG'!B:B,'Prod FG'!C:C,"-") -> 0 | E300: =IFERROR(D300*C300,"-") -> 0 | G300: =IFERROR(F300*C300,"-") -> 0

Sheet Sales
F1: =SUM(tbl_raw_sales7[Sales Kgs]) -> 16388.37
A2: =TODAY()-1 -> 46169 | F2: =SUMIF(A4:A129,A2,F4:F129) -> 16388.37
A3: Date | B3: Product Name | C3: Prod WT. | D3: Category | E3: Sales Qty | F3: Sales Kgs
A4: 46169 | B4: Powercool - 2 Ltr | C4: =_xlfn.XLOOKUP(B4,'Prod FG'!B:B,'Prod FG'!C:C,"-") -> 0.3905 | D4: Virgin | E4: 312 | F4: =IFERROR(E4*C4,"-") -> 121.836 | I4: Virgin | J4: =SUMIF(tbl_raw_sales7[Category],I4,tbl_raw_sales7[Sales Kgs]) -> 7472.2444
A5: 46169 | B5: Powercool - 3Ltr | C5: =_xlfn.XLOOKUP(B5,'Prod FG'!B:B,'Prod FG'!C:C,"-") -> 0.4788 | D5: Virgin | E5: 36 | F5: =IFERROR(E5*C5,"-") -> 17.2368 | I5: Recycled | J5: =SUMIF(tbl_raw_sales7[Category],I5,tbl_raw_sales7[Sales Kgs]) -> 6104.126
A6: 46169 | B6: Powercool - 5Ltr | C6: =_xlfn.XLOOKUP(B6,'Prod FG'!B:B,'Prod FG'!C:C,"-") -> 0.6475 | D6: Virgin | E6: 48 | F6: =IFERROR(E6*C6,"-") -> 31.08 | I6: Corporate | J6: =SUMIF(tbl_raw_sales7[Category],I6,tbl_raw_sales7[Sales Kgs]) -> 2812
A7: 46169 | B7: ZAFI CASSEROLE SET (2Ltr) | C7: =_xlfn.XLOOKUP(B7,'Prod FG'!B:B,'Prod FG'!C:C,"-") -> 0.3685 | D7: Recycled | E7: 0 | F7: =IFERROR(E7*C7,"-") -> 0
A8: 46169 | B8: ZAFI CASSEROLE SET (1.5 Ltr) | C8: =_xlfn.XLOOKUP(B8,'Prod FG'!B:B,'Prod FG'!C:C,"-") -> 0.232 | D8: Recycled | E8: 0 | F8: =IFERROR(E8*C8,"-") -> 0
A9: 46169 | B9: POWERCOOL 25 | C9: =_xlfn.XLOOKUP(B9,'Prod FG'!B:B,'Prod FG'!C:C,"-") -> 2.155 | D9: Virgin | E9: 0 | F9: =IFERROR(E9*C9,"-") -> 0
A10: 46169 | B10: POWERCOOL 35 | C10: =_xlfn.XLOOKUP(B10,'Prod FG'!B:B,'Prod FG'!C:C,"-") -> 3.05 | D10: Virgin | E10: 0 | F10: =IFERROR(E10*C10,"-") -> 0
A11: 46169 | B11: STAR FLOWER POT (LARGE) | C11: =_xlfn.XLOOKUP(B11,'Prod FG'!B:B,'Prod FG'!C:C,"-") -> 1.35 | D11: Recycled | E11: 0 | F11: =IFERROR(E11*C11,"-") -> 0
A12: 46169 | B12: STAR FLOWER POT (Medium) | C12: =_xlfn.XLOOKUP(B12,'Prod FG'!B:B,'Prod FG'!C:C,"-") -> 0.88 | D12: Recycled | E12: 0 | F12: =IFERROR(E12*C12,"-") -> 0
A13: 46169 | B13: STAR FLOWER POT (S) - 12 Pcs/Bag | C13: =_xlfn.XLOOKUP(B13,'Prod FG'!B:B,'Prod FG'!C:C,"-") -> 0.58 | D13: Recycled | E13: 0 | F13: =IFERROR(E13*C13,"-") -> 0
A14: 46169 | B14: DELUXE FLOWER POT | C14: =_xlfn.XLOOKUP(B14,'Prod FG'!B:B,'Prod FG'!C:C,"-") -> 0.27 | D14: Recycled | E14: 0 | F14: =IFERROR(E14*C14,"-") -> 0
A15: 46169 | B15: SUPER FLOWER POT | C15: =_xlfn.XLOOKUP(B15,'Prod FG'!B:B,'Prod FG'!C:C,"-") -> 0.385 | D15: Recycled | E15: 0 | F15: =IFERROR(E15*C15,"-") -> 0
A16: 46169 | B16: Storage Box Large (6 Pcs/Bag) | C16: =_xlfn.XLOOKUP(B16,'Prod FG'!B:B,'Prod FG'!C:C,"-") -> 1.5 | D16: Virgin | E16: 30 | F16: =IFERROR(E16*C16,"-") -> 45
A17: 46169 | B17: Storage Box Medium - (6pcs/Bag) | C17: =_xlfn.XLOOKUP(B17,'Prod FG'!B:B,'Prod FG'!C:C,"-") -> 0.904 | D17: Virgin | E17: 30 | F17: =IFERROR(E17*C17,"-") -> 27.12
A18: 46169 | B18: Storage Box Small - (12pcs/Bag) | C18: =_xlfn.XLOOKUP(B18,'Prod FG'!B:B,'Prod FG'!C:C,"-") -> 0.409 | D18: Virgin | E18: 120 | F18: =IFERROR(E18*C18,"-") -> 49.08
... A129: 46169 | B129: Papilon 100gm Container (500 Pcs/Bag) | C129: =_xlfn.XLOOKUP(B129,'Prod FG'!B:B,'Prod FG'!C:C,"-") -> 0.0095 | D129: Corporate | E129: 0 | F129: =IFERROR(E129*C129,"-") -> 0

Sheet Downtime
A1: =TODAY()-1 -> 46169 | D1: =SUMIF(A3:A100,A1,D3:D100) -> 44.08
A2: Date | B2: Mold/Machine | C2: Reason | D2: Duration (hrs)
A3: 46169 | B3: HT-49-IBM-50B | C3: Machine Breakdown | D3: 4.37 | H3: Count | I3: 53
A4: 46169 | B4: HT-31-HT-270 | C4: Machine Breakdown | D4: 0.55 | I4: =D1/I3 -> 0.83169811 | L4: Available Hrs for 53 Machines | M4: =53*24 -> 1272
A5: 46169 | B5: MI-15-HT-200 | C5: Machine Breakdown | D5: 1.08 | L5: Minimum Available Hrs Per Day | M5: =M4*0.8 -> 1017.6
A6: 46169 | B6: MI-16-HT-200 | C6: Machine Breakdown | D6: 1.63 | L6: Planned and Unplanned Downtime | M6: =M4-M5 -> 254.4
A7: 46169 | B7: MI-18-HT-250 | C7: Machine Breakdown | D7: 3.2 | M7: =M6/53 -> 4.8
A8: 46169 | B8: MI-18-HT-250 | C8: Machine Breakdown | D8: 1
A9: 46169 | B9: HT-34-FERO-200 | C9: Mould Breakdown | D9: 6
A10: 46169 | B10: HT-30-HT-270 | C10: Mould Breakdown | D10: 10
A11: 46169 | B11: HT-35-HXH-260 | C11: Mould Breakdown | D11: 2.45
A12: 46169 | B12: HT-34-FERO-200 | C12: Mould Breakdown | D12: 1.13
A13: 46169 | B13: HT-34-FERO-200 | C13: Mould Breakdown | D13: 0.25
A14: 46169 | B14: HT-30-HT-270 | C14: Mould Breakdown | D14: 0.33
A15: 46169 | B15: HT-30-HT-270 | C15: Mould Breakdown | D15: 1.33
A16: 46169 | B16: HT-30-HT-270 | C16: Mould Breakdown | D16: 1.92
A17: 46169 | B17: MI-11-HT-160 | C17: Mould Breakdown | D17: 3.13
A18: 46169 | B18: MI-12-HT-160 | C18: Mould Breakdown | D18: 1
A19: 46169 | B19: MI-26-OM-450 | C19: Mould Breakdown | D19: 0.73
... A21: 46169 | B21: LI-44-HXM-830 | C21: Mould Breakdown | D21: 1.38

Sheet Raw Materials
A1: =TODAY()-1 -> 46169 | C1: =SUMIF(A3:A95,A1,C3:C95) -> 873450.38 | D1: =SUMIF(A3:A95,A1,D3:D95) -> 214378 | E1: =SUMIF(A3:A95,A1,E3:E95) -> 373629.5 | F1: =SUMIF(A3:A95,A1,F3:F95) -> 714198.88
A2: Date | B2: Item | C2: Opening in Kgs | D2: Inward in Kgs | E2: Outward in Kgs | F2: Closing in Kgs
A3: 46169 | B3: PPHP Chair | C3: 206425 | D3: 1000 | E3: 87375 | F3: 120050
A4: 46169 | B4: Chair Grinding | C4: 103253.93 | D4: 29097 | E4: 32046.5 | F4: 100304.43
A5: 46169 | B5: Random High | C5: 110100 | D5: 0 | E5: 15725 | F5: 94375
A6: 46169 | B6: Random Low | C6: 92725 | D6: 0 | E6: 12275 | F6: 80450
A7: 46169 | B7: In-House Grinding | C7: 35646 | D7: 62376 | E7: 50175 | F7: 47847
A8: 46169 | B8: PPCP Chair | C8: 12200 | D8: 30000 | E8: 1350 | F8: 40850
A9: 46169 | B9: Blue Palletizer | C9: 34915 | D9: 8100 | E9: 2500 | F9: 40515
A10: 46169 | B10: Green Palletizer | C10: 30660 | D10: 10510 | E10: 785 | F10: 40385
A11: 46169 | B11: Raffia | C11: 59700 | D11: 1000 | E11: 22175 | F11: 38525
A12: 46169 | B12: Red Palletizer | C12: 17330 | D12: 2660 | E12: 35 | F12: 19955
A13: 46169 | B13: PPCP House | C13: 73000 | D13: 0 | E13: 57750 | F13: 15250
A14: 46169 | B14: HDPE Blow | C14: 0 | D14: 30000 | E14: 15650 | F14: 14350
... A95: 46169 | B95: Trans Pink | C95: 0 | D95: 0 | E95: 0 | F95: 0

Sheet Manpower
A1: =TODAY()-1 -> 46169 | C1: =SUMIF(A3:A14,A1,C3:C14) -> 197 | D1: =SUMIF(A3:A14,A1,D3:D14) -> 185 | E1: =SUMIF(A3:A14,A1,E3:E14) -> 12
A2: Date | B2: Department | C2: Target Headcount | D2: Present | E2: Absent
A3: 46169 | B3: Large Injection | C3: 30 | D3: 28 | E3: =IFERROR(tbl_raw_manpower[[#This Row],[Target Headcount]]-tbl_raw_manpower[[#This Row],[Present]],"-") -> 2
A4: 46169 | B4: Modern Injection | C4: 80 | D4: 78 | E4: =IFERROR(tbl_raw_manpower[[#This Row],[Target Headcount]]-tbl_raw_manpower[[#This Row],[Present]],"-") -> 2
A5: 46169 | B5: Hi-Tech | C5: 40 | D5: 38 | E5: =IFERROR(tbl_raw_manpower[[#This Row],[Target Headcount]]-tbl_raw_manpower[[#This Row],[Present]],"-") -> 2
A6: 46169 | B6: IBM Section | C6: 10 | D6: 8 | E6: =IFERROR(tbl_raw_manpower[[#This Row],[Target Headcount]]-tbl_raw_manpower[[#This Row],[Present]],"-") -> 2
A7: 46169 | B7: Blow Section | C7: 7 | D7: 6 | E7: =IFERROR(tbl_raw_manpower[[#This Row],[Target Headcount]]-tbl_raw_manpower[[#This Row],[Present]],"-") -> 1
A8: 46169 | B8: TFM Extrusion | C8: 30 | D8: 27 | E8: =IFERROR(tbl_raw_manpower[[#This Row],[Target Headcount]]-tbl_raw_manpower[[#This Row],[Present]],"-") -> 3
A9: 46169 | E9: =IFERROR(tbl_raw_manpower[[#This Row],[Target Headcount]]-tbl_raw_manpower[[#This Row],[Present]],"-") -> 0
A10: 46169 | E10: =IFERROR(tbl_raw_manpower[[#This Row],[Target Headcount]]-tbl_raw_manpower[[#This Row],[Present]],"-") -> 0
A11: 46169 | E11: =IFERROR(tbl_raw_manpower[[#This Row],[Target Headcount]]-tbl_raw_manpower[[#This Row],[Present]],"-") -> 0
A12: 46169 | E12: =IFERROR(tbl_raw_manpower[[#This Row],[Target Headcount]]-tbl_raw_manpower[[#This Row],[Present]],"-") -> 0
A13: 46169 | E13: =IFERROR(tbl_raw_manpower[[#This Row],[Target Headcount]]-tbl_raw_manpower[[#This Row],[Present]],"-") -> 0
A14: 46169 | E14: =IFERROR(tbl_raw_manpower[[#This Row],[Target Headcount]]-tbl_raw_manpower[[#This Row],[Present]],"-") -> 0

Sheet Calculations
A4: Total Production (Kgs)
A5: Achieved | B5: =Production!E1 -> 30540.396
A6: Target | B6: 42000
A7: Var % | B7: =-(B5-B6)/B6 -> 0.27284771
A8: Sales Kgs
A9: Achieved | B9: ='Production vs Sales'!G1 -> 16388.37
A10: Target | B10: ='Production vs Sales'!M1 -> 30000
A11: Var % | B11: =-(B9-B10)/B10 -> 0.45372099
A12: Production Efficiency | B12: =IFERROR(B5/B6,"-") -> 0.72715229
A13: Production Target | B13: 1
A14: Var % | B14: =-(B12-B13)/B13 -> 0.27284771
A15: Downtime (Hrs) | B15: =Downtime!D1 -> 44.08
A16: Downtime Target (Hrs) | B16: =Downtime!M6 -> 254.4
A17: Var % | B17: =B15/B16 -> 0.17327044
A18: Total RM Stock (Kg) | B18: ='Raw Materials'!F1 -> 714198.88
A19: Total Inward (Kg) | B19: ='Raw Materials'!D1 -> 214378
A20: Total Outward (Kg) | B20: ='Raw Materials'!E1 -> 373629.5
A21: Today's FG. Transfer (Kg) | B21: 30867
A22: Target | B22: 35000
A23: Total FG Stock (Kg) | B23: ='FG Store'!F1 -> 389028.68
A24: Var % | B24: =-(B21-B22)/B22 -> 0.11808571
A25: Energy Consumed (kwh) | B25: 34278
A26: Target | B26: 1
A27: Per Kg: | B27: 1.35
A28: Var % | B28: =(B27-B26)/B26 -> 0.35
A29: Total FG Inward (Kg) | B29: =B21 -> 30867
A30: SFG Opening (Kg) | B30: 25737
A31: Total Inward (Kg) | B31: 740
A32: Total Outward (Kg) | B32: 315
A33: Total SFG Stock (Kg) | B33: =IFERROR(B30+B31-B32,"-") -> 26162
A34: Total Manpower | B34: 248
A35: Present | B35: 232
A36: Absent | B36: 16
A37: Washing Line
A38: Target in Kgs | B38: 6000
A39: Achieved in Kgs | B39: 2187
A40: Recycling Department
A41: Target in Kgs | B41: 5000
A42: Achieved in Kgs | B42: 6670
A43: Mold Breakdown | B43: 4
...

Sheet Prod FG
A1: S/N | B1: Product Name | C1: Prod WT
A2: 1 | B2: Powercool - 2 Ltr | C2: 0.3905
A3: 2 | B3: ZAFI CASSEROLE SET (1.5 Ltr) | C3: 0.232
B4: ZAFI CASSEROLE SET (2Ltr) | C4: 0.3685
A5: 3 | B5: ZAFI CASSEROLE SET 2 (1.5/2Ltr) | C5: 0.7368
A6: 4 | B6: POWERCOOL 25 | C6: 2.155
A7: 5 | B7: POWERCOOL 35 | C7: 3.05
A8: 6 | B8: Powercool - 3Ltr | C8: 0.4788
A9: 7 | B9: Powercool - 5Ltr | C9: 0.6475
A10: 8 | B10: POWERCOOL 60 | C10: 4.79
A11: 9 | B11: Powercool - 8Ltr | C11: 0.993
A12: 10 | B12: 13ltr Crystal Bucket - Branded | C12: 0.378
A13: 11 | B13: 8 Ltr Basin - Branded - Inactive | C13: 0.235
A14: 12 | B14: Amore 9 Ltr Bucket with Cover - Branded (12pcs/Bag) | C14: 0.315
A15: 13 | B15: Amore 9 Ltr Bucket Without Cover - Branded (12pcs/Bag) | C15: 0.22
A16: 14 | B16: Leo Decorated 12ltr Bucket Without Cover - Branded (12pcs/Bag) | C16: 0.332
... A206: 204 | B206: PP 1000 Star Pack | C206: 0.0283
